Workbook

Sheet Hoja1
A1: Detalle de la Inspección
A2: Normal
A3: Despolarizado
A4: Inversa [Interferencias]
A5: Tipo de Ducto
A6: Troncal
A7: Loop
A8: Ramal
A9: Justificación
A10: Monitoreo
A11: Ocupaciones
A12: Estudio Interferencias
... A41: Caño
A42: Línea BT | B42: Línea Baja Tensión
A43: Línea MT | B43: Línea Media Tensión
A44: Línea Alta Tensión | B44: Línea Alta Tensión
A45: Maro H
A46: Tubería Expuesta | B46: Tubería de condición normal enterrada y quedó expuesta
A47: Tubería Soterrada | B47: Tubería de condición normal aérea y quedó semienterrada
A48: Puente Ducto
A50: Bueno
A51: Regular
A52: Malo
A54: Bueno
A55: Malo
A58: Sale de la Tubería
A59: Ingresa a la Tubería
A62: TIPO DE HALLAZGO
A63: Tubería Expuesta
A64: Tubería Soterrada
A65: Marco H sin Aislamiento
... A87: Grande

Sheet Informe
H1: GERENCIA DE INTEGRIDAD Y CONFIABILIDAD INSPECCIÓN DCVG | AC1: Código:
AC3: Revisión:
AC4: Emisión:
AC5: Página _ de _
A6: Fecha | R6: Serial equipo | AA6: No de contrato | AE6: 551007370
A7: Gasoducto | G7: Mariquita_Cali | R7: Fecha calibración Eqp | AA7: Contratista | AE7: PCC
A8: Tramo | R8: Tipo de recubrimiento | AA8: OT
A9: Inspector | R9: Diámetro | AA9: Ciclo | AE9: 1.6 ON -0.4 OFF
A11: OBJETIVO
A12: Realizar un diagnóstico del estado general del recubrimiento, bajo la técnica de inspección DCVG para la tubería enterrada e inspección visual para la tubería aérea del Ramal Villa María, el cual hace parte del gasoducto Mariquita - Cali perteneciente al distrito 7. Clasificar puntos estratégicos susceptibles a falla a corto plazo del recubrimiento, para definir programas de mantenimiento y reparación.
A13: DOCUMENTOS DE REFERENCIA
A14: NACE-SP0169-2024 Control of External Corrosión on Underground or Submerged Metallic Piping Systems.
A15: NACE -TM0497-2018-SG Measurement Techniques Related to Criteria for Cathodic Protection on Underground or Submerged Metallic Piping Systems
A16: NACE -TM0497-2018-SG Measurement Techniques Related to Criteria for Cathodic Protection on Underground or Submerged Metallic Piping Systems
A18: EQUIPOS UTILIZADOS
A19: - Electrodos de Referencia: 2 Mc Miller | S19: - Osciloscopio: IBTVM-06582
A20: - Localizador de tubería: Radiodetection-1211 | S20: - Cámara fotográfica
A21: - Equipo GPS: IBTVM-06582 | S21: - Medidor aislamientos: Tinker and Rasor RF-IT - 6970
A22: - Multímetro: UEI INSTRUMENTS -231100950
A23: - Interruptores de corriente: Radiodetection - 572, 633 Y 574
A25: DESCRIPCIÓN DE LA LÍNEA OBJETO DE ESTUDIO
A27: ANTECEDENTES
A29: }
A30: PUNTO INICIAL:
G31: 0 | L31: LATITUD: | P31: 5.0138888 | U31: LONGITUD: | V31: -75.495526 | AA31: ALTURA: | AB31: 2443 msnm
A32: PUNTO FINAL: | G32: 4000 | L32: LATITUD: | P32: 5.033819 | U32: LONGITUD: | V32: -75.508276 | AA32: ALTURA: | AB32: 2053 msnm
A33: TIPO DE INSPECCIÓN: | G33: DCVG | L33: DETALLE DE INSPECCIÓN: | P33: Inspección indirecta del estado del Recubrimiento | U33: JUSTIFICACIÓN: | V33: Monitoreo | AA33: USO DE TIERRA: | AB33: Agricultura
A34: AMENAZA: | G34: CORROSIÓN EXTERNA | L34: TIPO DE DUCTO: | P34: Ramal | U34: TIPO SPC: | V34: Corriente Impresa | W34: TOPOGRAFÍA Y TIPO DE SUELO: | AB34: Montañoso
A35: LONGITUD TOTAL DE LA LÍNEA AÉREA[km]: | G35: 0 | L35: LONGITUD TOTAL DE LA LÍNEA AÉREA INSPECCIOANDA [Km]: | P35: 0
A36: LONGITUD TOTAL DE LA LÍNEA ENTERRADA[km]: | G36: 4 | L36: LONGITUD TOTAL DE LA LÍNEA ENTERRADA INSPECCIOANDA [Km]: | P36: 4
A38: GENERALIDADES
A40: DEFECTOS/KILÓMETRO: | G40: =T58/(P36*1000)*1000 -> 0 | L40: CICLO ON[s] | P40: 1.6 | U40: CICLO OFF [s]: | V40: 0.4
B43: PARÁMETROS OPERATIVOS EN RECTIFICADORES DE INFLUENCIA
B44: URPC | E44: DATOS NOMINALES | K44: DATOS OPERACIONALES | O44: DISPONIBILIDAD | S44: TAPS [GRUESO - FINO] | T44: POTENCIAL ON-INSTANT OFF NEGATIVOS | Z44: CORRIENTE NEGATIVOS
E45: VOLTAJE DE SALIDA [VDC] | H45: CORRIENTE DE SALIDA [ADC] | K45: VOLTAJE DE SALIDA [VDC] | N45: CORRIENTE DE SALIDA [ADC] | O45: VOLTAJE DE SALIDA [%] | Q45: CORRIENTE DE SALIDA [%] | T45: NEG 1 [mV] | V45: NEG 2 [mV] | W45: NEG 3 [mV] | Z45: NEG 1 [A] | AB45: NEG 2 [A] | AF45: NEG 3 [A]
B53: RESUMEN DE INDICACIONES
B54: CARÁCTER [ON-OFF] | H54: SEVERIDAD MUY PEQUEÑO [%IR: 1-15] | K54: SEVERIDAD PEQUEÑO [%IR: 16-35] | O54: SEVERIDAD MEDIANA [%IR: 36-60] | Q54: SEVERIDAD GRANDE [%IR: 61-100] | T54: Total
B55: AA | H55: =COUNTIFS('Inspección DCVG'!V8:V37,"Muy pequeño",'Inspección DCVG'!$L$8:$L$37,"AA") -> 0 | K55: =COUNTIFS('Inspección DCVG'!V8:V237,"Pequeño",'Inspección DCVG'!$L$8:$L$237,"A-A") -> 0 | O55: =COUNTIFS('Inspección DCVG'!V8:V237,"Mediana",'Inspección DCVG'!$L$8:$L$237,"A-A") -> 0 | Q55: =COUNTIFS('Inspección DCVG'!V8:V237,"Grande",'Inspección DCVG'!$L$8:$L$237,"A-A") -> 0 | T55: =+SUM(H55:S55) -> 0
B56: CA | H56: =COUNTIFS('Inspección DCVG'!V8:V237,"Muy pequeño",'Inspección DCVG'!$L$8:$L$237,"CA") -> 0 | K56: =COUNTIFS('Inspección DCVG'!V8:V237,"Pequeño",'Inspección DCVG'!$L$8:$L$237,"CA") -> 0 | O56: =COUNTIFS('Inspección DCVG'!V8:V237,"Mediana",'Inspección DCVG'!$L$8:$L$237,"CA") -> 0 | Q56: =COUNTIFS('Inspección DCVG'!V8:V237,"Grande",'Inspección DCVG'!$L$8:$L$237,"CA") -> 0 | T56: =+SUM(H56:S56) -> 0
B57: CC | H57: =COUNTIFS('Inspección DCVG'!V8:V237,"Muy pequeño",'Inspección DCVG'!$L$8:$L$237,"CC") -> 0 | K57: =COUNTIFS('Inspección DCVG'!V8:V237,"Pequeño",'Inspección DCVG'!$L$8:$L$237,"CC") -> 0 | O57: =COUNTIFS('Inspección DCVG'!V8:V237,"Mediana",'Inspección DCVG'!$L$8:$L$237,"CC") -> 0 | Q57: =COUNTIFS('Inspección DCVG'!V8:V237,"Grande",'Inspección DCVG'!$L$8:$L$237,"CC") -> 0 | T57: =+SUM(H57:S57) -> 0
...

Sheet Inspección DCVG
D1: GERENCIA DE INTEGRIDAD Y CONFIABILIDAD INSPECCIÓN DCVG | X1: Código:
X2: Revisión:
X3: Emisión:
X4: Página _ de _
A6: ÍTEM | B6: REFERENCIAS GEOGRÁFICAS | C6: DISTANCIA TRAMO [m] | D6: ABSCISA | E6: LATITUD | F6: LONGITUD | G6: ALTITUD [msnm] | H6: FORMA [mV] | L6: CARÁCTER | M6: OL/RE [mV] | N6: POTENCIAL ESTRUCTURA-SUELO [mV] | P6: PULSO [mV] | Q6: P/RE [mV] | R6: PROFUNDIDAD [cm] | S6: SEVERIDAD [%IR] | V6: SEVERIDAD [CLASIFICACIÓN] | W6: RESISTIVIDAD [Ohm-cm] | X6: OBSERVACIONES
H7: 12 | I7: 3 | J7: 6 | K7: 9 | L7: ON-OFF | N7: ON | O7: OFF | S7: AA | T7: CA | U7: CC
C239: ELABORÓ | G239: REVISÓ | T239: APROBÓ
A240: Nombre | C240: =Informe!D99 -> 0 | G240: =Informe!O99 -> 0 | T240: =Informe!W99 -> Alejando Rivera
A241: Cargo | C241: =Informe!D100 -> Ingeniero Junior | G241: =Informe!O100 -> Ingeniero Residente | T241: =Informe!W100 -> Coordinador de Proyectos
A242: Empresa | C242: =Informe!D101 -> Protección Catódica de Colombia SAS | G242: =Informe!O101 -> Protección Catódica de Colombia SAS | T242: =Informe!W101 -> Protección Catódica de Colombia SAS

Sheet Hoja2
D2: 139120
D3: 139180 | E3: =D3-D2 -> 60
D4: 151580
D5: 151620 | E5: =D5-D4 -> 40
D6: 153760
D7: 153980 | E7: =+D7-D6 -> 220
D8: 163450
D9: 163480 | E9: =+D9-D8 -> 30
D10: 163560
D11: 163600 | E11: =+D11-D10 -> 40
D12: 164025
D13: 164050 | E13: =+D13-D12 -> 25
D14: 164120
D15: 164150 | E15: =+D15-D14 -> 30
D16: 164320
D17: 164370 | E17: =+D17-D16 -> 50
D18: 165265
D19: 165280 | E19: =+D19-D18 -> 15
D20: 165690
D21: 165710 | E21: =+D21-D20 -> 20
D22: 165875
D23: 165910 | E23: =+D23-D22 -> 35
D24: 166350
D25: 166420 | E25: =+D25-D24 -> 70
D26: 168340
D27: 168370 | E27: =+D27-D26 -> 30
D28: 171555
D29: 171580 | E29: =D29-D28 -> 25
E30: =SUM(E1:E29) -> 690

Sheet GRAFICA DCVG
E3: GERENCIA DE INTEGRIDAD Y CONFIABILIDAD INSPECCIÓN DCVG | J3: Código:
J5: Revisión:
J6: Emisión:
J7: Página _ de _
O18: ñ
C31: FECHA: | D31: =Informe!G6 -> 0 | F31: OBSERVACIONES
C32: GASODUCTO: | D32: =Informe!G7 -> Mariquita_Cali | F32: En el Ramal Villa María se identificaron tres (3) indicaciones, con una densidad de defectos de 0,75 Indicaciones/Km. En donde las tres (3) indicaciones tienen un índice de severidad IR menor a 15%. De lo anterior se puede observar que las tres (3) indicaciones son de carácter AA.
C33: TRAMO | D33: =Informe!G8 -> 0
C34: LONGITUD: | D34: =Informe!G36+Informe!G35 -> 4
C35: DIÁMETRO: | D35: =Informe!U9 -> 0
C36: RECUBRIMIENTO: | D36: =Informe!U8 -> 0
D39: 0 | E39: 15 | F39: 35 | G39: 60
D40: 4000 | E40: 15 | F40: 35 | G40: 60

Sheet Resistividad
D1: GERENCIA DE INTEGRIDAD Y CONFIABILIDAD MEDICION RESISTIVIDAD DE SUELO METODO WENNER 4 PINES | R1: Código: Revisión: Emisión: Página _ de _
A3: Fecha | D3: =Informe!G6 -> 0 | K3: Serial equipo | N3: =Informe!U6 -> 0 | R3: No Contrato | S3: =Informe!AE6 -> 551007370
A4: Gasoducto | D4: =Informe!G7 -> Mariquita_Cali | K4: Fecha calibración Eqp | N4: =Informe!U7 -> 0 | R4: Contratista | S4: =Informe!AE7 -> PCC
A5: Tramo | D5: =Informe!G8 -> 0 | K5: Tipo de recubrimiento | N5: =Informe!U8 -> 0 | R5: OT | S5: =Informe!AE8 -> 0
A6: Inspector | D6: =Informe!G9 -> 0 | K6: Diámetro | N6: =Informe!U9 -> 0 | R6: Ciclo | S6: =Informe!AE9 -> 1.6 ON -0.4 OFF
A7: ABSCISADO | B7: DESCRIPCIÓN | C7: GEORREFERENCIACIÓN | F7: RESISTENCIA MEDIDA [Ohm] | L7: RESISTIVIDAD APARENTE [Ohm-cm] | R7: RESISTIVIDAD DE CAPA [Ohm-cm]
C8: Latitud | D8: Longitud | E8: Profundidad | F8: S1 = | G8: 1 m | H8: S2 = | I8: 2 m | J8: S3= | K8: 3 m | L8: ρ1 | N8: ρ2 | P8: ρ3 | R8: ρC1 | S8: ρC2 | T8: ρC3
L9: =2*PI()*F9*100 -> 0 | N9: =2*PI()*H9*200 -> 0 | P9: =2*PI()*J9*300 -> 0 | R9: =2*PI()*F9*100 -> 0 | S9: =((F9*H9)/(ABS(H9-F9)))*2*PI()*100 -> #DIV/0! | T9: =((H9*J9)/(ABS(J9-H9)))*2*PI()*100 -> #DIV/0! | U9: =IF(R9<=500,"Muy Corrosivo",IF(R9<=1000,"Corrosivo",IF(R9<=2000,"Moderadamente Corrosivo",IF(R9<=10000,"Medianamente Corrosivo",IF(R9>10000,"Despreciable","N/A"))))) -> Muy Corrosivo | V9: =IF(S9<=500,"Muy Corrosivo",IF(S9<=1000,"Corrosivo",IF(S9<=2000,"Moderadamente Corrosivo",IF(S9<=10000,"Medianamente Corrosivo",IF(S9>10000,"Despreciable","N/A"))))) -> #DIV/0! | W9: =IF(T9<=500,"Muy Corrosivo",IF(T9<=1000,"Corrosivo",IF(T9<=2000,"Moderadamente Corrosivo",IF(T9<=10000,"Medianamente Corrosivo",IF(T9>10000,"Despreciable","N/A"))))) -> #DIV/0!
L10: =2*PI()*F10*100 -> 0 | N10: =2*PI()*H10*200 -> 0 | P10: =2*PI()*J10*300 -> 0 | R10: =2*PI()*F10*100 -> 0 | S10: =((F10*H10)/(ABS(H10-F10)))*2*PI()*100 -> #DIV/0! | T10: =((H10*J10)/(ABS(J10-H10)))*2*PI()*100 -> #DIV/0! | U10: =IF(R10<=500,"Muy Corrosivo",IF(R10<=1000,"Corrosivo",IF(R10<=2000,"Moderadamente Corrosivo",IF(R10<=10000,"Medianamente Corrosivo",IF(R10>10000,"Despreciable","N/A"))))) -> Muy Corrosivo | V10: =IF(S10<=500,"Muy Corrosivo",IF(S10<=1000,"Corrosivo",IF(S10<=2000,"Moderadamente Corrosivo",IF(S10<=10000,"Medianamente Corrosivo",IF(S10>10000,"Despreciable","N/A"))))) -> #DIV/0! | W10: =IF(T10<=500,"Muy Corrosivo",IF(T10<=1000,"Corrosivo",IF(T10<=2000,"Moderadamente Corrosivo",IF(T10<=10000,"Medianamente Corrosivo",IF(T10>10000,"Despreciable","N/A"))))) -> #DIV/0!
L11: =2*PI()*F11*100 -> 0 | N11: =2*PI()*H11*200 -> 0 | P11: =2*PI()*J11*300 -> 0 | R11: =2*PI()*F11*100 -> 0 | S11: =((F11*H11)/(ABS(H11-F11)))*2*PI()*100 -> #DIV/0! | T11: =((H11*J11)/(ABS(J11-H11)))*2*PI()*100 -> #DIV/0! | U11: =IF(R11<=500,"Muy Corrosivo",IF(R11<=1000,"Corrosivo",IF(R11<=2000,"Moderadamente Corrosivo",IF(R11<=10000,"Medianamente Corrosivo",IF(R11>10000,"Despreciable","N/A"))))) -> Muy Corrosivo | V11: =IF(S11<=500,"Muy Corrosivo",IF(S11<=1000,"Corrosivo",IF(S11<=2000,"Moderadamente Corrosivo",IF(S11<=10000,"Medianamente Corrosivo",IF(S11>10000,"Despreciable","N/A"))))) -> #DIV/0! | W11: =IF(T11<=500,"Muy Corrosivo",IF(T11<=1000,"Corrosivo",IF(T11<=2000,"Moderadamente Corrosivo",IF(T11<=10000,"Medianamente Corrosivo",IF(T11>10000,"Despreciable","N/A"))))) -> #DIV/0!
L12: =2*PI()*F12*100 -> 0 | N12: =2*PI()*H12*200 -> 0 | P12: =2*PI()*J12*300 -> 0 | R12: =2*PI()*F12*100 -> 0 | S12: =((F12*H12)/(ABS(H12-F12)))*2*PI()*100 -> #DIV/0! | T12: =((H12*J12)/(ABS(J12-H12)))*2*PI()*100 -> #DIV/0! | U12: =IF(R12<=500,"Muy Corrosivo",IF(R12<=1000,"Corrosivo",IF(R12<=2000,"Moderadamente Corrosivo",IF(R12<=10000,"Medianamente Corrosivo",IF(R12>10000,"Despreciable","N/A"))))) -> Muy Corrosivo | V12: =IF(S12<=500,"Muy Corrosivo",IF(S12<=1000,"Corrosivo",IF(S12<=2000,"Moderadamente Corrosivo",IF(S12<=10000,"Medianamente Corrosivo",IF(S12>10000,"Despreciable","N/A"))))) -> #DIV/0! | W12: =IF(T12<=500,"Muy Corrosivo",IF(T12<=1000,"Corrosivo",IF(T12<=2000,"Moderadamente Corrosivo",IF(T12<=10000,"Medianamente Corrosivo",IF(T12>10000,"Despreciable","N/A"))))) -> #DIV/0!
L13: =2*PI()*F13*100 -> 0 | N13: =2*PI()*H13*200 -> 0 | P13: =2*PI()*J13*300 -> 0 | R13: =2*PI()*F13*100 -> 0 | S13: =((F13*H13)/(ABS(H13-F13)))*2*PI()*100 -> #DIV/0! | T13: =((H13*J13)/(ABS(J13-H13)))*2*PI()*100 -> #DIV/0! | U13: =IF(R13<=500,"Muy Corrosivo",IF(R13<=1000,"Corrosivo",IF(R13<=2000,"Moderadamente Corrosivo",IF(R13<=10000,"Medianamente Corrosivo",IF(R13>10000,"Despreciable","N/A"))))) -> Muy Corrosivo | V13: =IF(S13<=500,"Muy Corrosivo",IF(S13<=1000,"Corrosivo",IF(S13<=2000,"Moderadamente Corrosivo",IF(S13<=10000,"Medianamente Corrosivo",IF(S13>10000,"Despreciable","N/A"))))) -> #DIV/0! | W13: =IF(T13<=500,"Muy Corrosivo",IF(T13<=1000,"Corrosivo",IF(T13<=2000,"Moderadamente Corrosivo",IF(T13<=10000,"Medianamente Corrosivo",IF(T13>10000,"Despreciable","N/A"))))) -> #DIV/0!
L14: =2*PI()*F14*100 -> 0 | N14: =2*PI()*H14*200 -> 0 | P14: =2*PI()*J14*300 -> 0 | R14: =2*PI()*F14*100 -> 0 | S14: =((F14*H14)/(ABS(H14-F14)))*2*PI()*100 -> #DIV/0! | T14: =((H14*J14)/(ABS(J14-H14)))*2*PI()*100 -> #DIV/0! | U14: =IF(R14<=500,"Muy Corrosivo",IF(R14<=1000,"Corrosivo",IF(R14<=2000,"Moderadamente Corrosivo",IF(R14<=10000,"Medianamente Corrosivo",IF(R14>10000,"Despreciable","N/A"))))) -> Muy Corrosivo | V14: =IF(S14<=500,"Muy Corrosivo",IF(S14<=1000,"Corrosivo",IF(S14<=2000,"Moderadamente Corrosivo",IF(S14<=10000,"Medianamente Corrosivo",IF(S14>10000,"Despreciable","N/A"))))) -> #DIV/0! | W14: =IF(T14<=500,"Muy Corrosivo",IF(T14<=1000,"Corrosivo",IF(T14<=2000,"Moderadamente Corrosivo",IF(T14<=10000,"Medianamente Corrosivo",IF(T14>10000,"Despreciable","N/A"))))) -> #DIV/0!
L15: =2*PI()*F15*100 -> 0 | N15: =2*PI()*H15*200 -> 0 | P15: =2*PI()*J15*300 -> 0 | R15: =2*PI()*F15*100 -> 0 | S15: =((F15*H15)/(ABS(H15-F15)))*2*PI()*100 -> #DIV/0! | T15: =((H15*J15)/(ABS(J15-H15)))*2*PI()*100 -> #DIV/0! | U15: =IF(R15<=500,"Muy Corrosivo",IF(R15<=1000,"Corrosivo",IF(R15<=2000,"Moderadamente Corrosivo",IF(R15<=10000,"Medianamente Corrosivo",IF(R15>10000,"Despreciable","N/A"))))) -> Muy Corrosivo | V15: =IF(S15<=500,"Muy Corrosivo",IF(S15<=1000,"Corrosivo",IF(S15<=2000,"Moderadamente Corrosivo",IF(S15<=10000,"Medianamente Corrosivo",IF(S15>10000,"Despreciable","N/A"))))) -> #DIV/0! | W15: =IF(T15<=500,"Muy Corrosivo",IF(T15<=1000,"Corrosivo",IF(T15<=2000,"Moderadamente Corrosivo",IF(T15<=10000,"Medianamente Corrosivo",IF(T15>10000,"Despreciable","N/A"))))) -> #DIV/0!
L16: =2*PI()*F16*100 -> 0 | N16: =2*PI()*H16*200 -> 0 | P16: =2*PI()*J16*300 -> 0 | R16: =2*PI()*F16*100 -> 0 | S16: =((F16*H16)/(ABS(H16-F16)))*2*PI()*100 -> #DIV/0! | T16: =((H16*J16)/(ABS(J16-H16)))*2*PI()*100 -> #DIV/0! | U16: =IF(R16<=500,"Muy Corrosivo",IF(R16<=1000,"Corrosivo",IF(R16<=2000,"Moderadamente Corrosivo",IF(R16<=10000,"Medianamente Corrosivo",IF(R16>10000,"Despreciable","N/A"))))) -> Muy Corrosivo | V16: =IF(S16<=500,"Muy Corrosivo",IF(S16<=1000,"Corrosivo",IF(S16<=2000,"Moderadamente Corrosivo",IF(S16<=10000,"Medianamente Corrosivo",IF(S16>10000,"Despreciable","N/A"))))) -> #DIV/0! | W16: =IF(T16<=500,"Muy Corrosivo",IF(T16<=1000,"Corrosivo",IF(T16<=2000,"Moderadamente Corrosivo",IF(T16<=10000,"Medianamente Corrosivo",IF(T16>10000,"Despreciable","N/A"))))) -> #DIV/0!
L17: =2*PI()*F17*100 -> 0 | N17: =2*PI()*H17*200 -> 0 | P17: =2*PI()*J17*300 -> 0 | R17: =2*PI()*F17*100 -> 0 | S17: =((F17*H17)/(ABS(H17-F17)))*2*PI()*100 -> #DIV/0! | T17: =((H17*J17)/(ABS(J17-H17)))*2*PI()*100 -> #DIV/0! | U17: =IF(R17<=500,"Muy Corrosivo",IF(R17<=1000,"Corrosivo",IF(R17<=2000,"Moderadamente Corrosivo",IF(R17<=10000,"Medianamente Corrosivo",IF(R17>10000,"Despreciable","N/A"))))) -> Muy Corrosivo | V17: =IF(S17<=500,"Muy Corrosivo",IF(S17<=1000,"Corrosivo",IF(S17<=2000,"Moderadamente Corrosivo",IF(S17<=10000,"Medianamente Corrosivo",IF(S17>10000,"Despreciable","N/A"))))) -> #DIV/0! | W17: =IF(T17<=500,"Muy Corrosivo",IF(T17<=1000,"Corrosivo",IF(T17<=2000,"Moderadamente Corrosivo",IF(T17<=10000,"Medianamente Corrosivo",IF(T17>10000,"Despreciable","N/A"))))) -> #DIV/0!
L18: =2*PI()*F18*100 -> 0 | N18: =2*PI()*H18*200 -> 0 | P18: =2*PI()*J18*300 -> 0 | R18: =2*PI()*F18*100 -> 0 | S18: =((F18*H18)/(ABS(H18-F18)))*2*PI()*100 -> #DIV/0! | T18: =((H18*J18)/(ABS(J18-H18)))*2*PI()*100 -> #DIV/0! | U18: =IF(R18<=500,"Muy Corrosivo",IF(R18<=1000,"Corrosivo",IF(R18<=2000,"Moderadamente Corrosivo",IF(R18<=10000,"Medianamente Corrosivo",IF(R18>10000,"Despreciable","N/A"))))) -> Muy Corrosivo | V18: =IF(S18<=500,"Muy Corrosivo",IF(S18<=1000,"Corrosivo",IF(S18<=2000,"Moderadamente Corrosivo",IF(S18<=10000,"Medianamente Corrosivo",IF(S18>10000,"Despreciable","N/A"))))) -> #DIV/0! | W18: =IF(T18<=500,"Muy Corrosivo",IF(T18<=1000,"Corrosivo",IF(T18<=2000,"Moderadamente Corrosivo",IF(T18<=10000,"Medianamente Corrosivo",IF(T18>10000,"Despreciable","N/A"))))) -> #DIV/0!
L19: =2*PI()*F19*100 -> 0 | N19: =2*PI()*H19*200 -> 0 | P19: =2*PI()*J19*300 -> 0 | R19: =2*PI()*F19*100 -> 0 | S19: =((F19*H19)/(ABS(H19-F19)))*2*PI()*100 -> #DIV/0! | T19: =((H19*J19)/(ABS(J19-H19)))*2*PI()*100 -> #DIV/0! | U19: =IF(R19<=500,"Muy Corrosivo",IF(R19<=1000,"Corrosivo",IF(R19<=2000,"Moderadamente Corrosivo",IF(R19<=10000,"Medianamente Corrosivo",IF(R19>10000,"Despreciable","N/A"))))) -> Muy Corrosivo | V19: =IF(S19<=500,"Muy Corrosivo",IF(S19<=1000,"Corrosivo",IF(S19<=2000,"Moderadamente Corrosivo",IF(S19<=10000,"Medianamente Corrosivo",IF(S19>10000,"Despreciable","N/A"))))) -> #DIV/0! | W19: =IF(T19<=500,"Muy Corrosivo",IF(T19<=1000,"Corrosivo",IF(T19<=2000,"Moderadamente Corrosivo",IF(T19<=10000,"Medianamente Corrosivo",IF(T19>10000,"Despreciable","N/A"))))) -> #DIV/0!
L20: =2*PI()*F20*100 -> 0 | N20: =2*PI()*H20*200 -> 0 | P20: =2*PI()*J20*300 -> 0 | R20: =2*PI()*F20*100 -> 0 | S20: =((F20*H20)/(ABS(H20-F20)))*2*PI()*100 -> #DIV/0! | T20: =((H20*J20)/(ABS(J20-H20)))*2*PI()*100 -> #DIV/0! | U20: =IF(R20<=500,"Muy Corrosivo",IF(R20<=1000,"Corrosivo",IF(R20<=2000,"Moderadamente Corrosivo",IF(R20<=10000,"Medianamente Corrosivo",IF(R20>10000,"Despreciable","N/A"))))) -> Muy Corrosivo | V20: =IF(S20<=500,"Muy Corrosivo",IF(S20<=1000,"Corrosivo",IF(S20<=2000,"Moderadamente Corrosivo",IF(S20<=10000,"Medianamente Corrosivo",IF(S20>10000,"Despreciable","N/A"))))) -> #DIV/0! | W20: =IF(T20<=500,"Muy Corrosivo",IF(T20<=1000,"Corrosivo",IF(T20<=2000,"Moderadamente Corrosivo",IF(T20<=10000,"Medianamente Corrosivo",IF(T20>10000,"Despreciable","N/A"))))) -> #DIV/0!
... L25: =2*PI()*F25*100 -> 0 | N25: =2*PI()*H25*200 -> 0 | P25: =2*PI()*J25*300 -> 0 | R25: =2*PI()*F25*100 -> 0 | S25: =((F25*H25)/(ABS(H25-F25)))*2*PI()*100 -> #DIV/0! | T25: =((H25*J25)/(ABS(J25-H25)))*2*PI()*100 -> #DIV/0! | U25: =IF(R25<=500,"Muy Corrosivo",IF(R25<=1000,"Corrosivo",IF(R25<=2000,"Moderadamente Corrosivo",IF(R25<=10000,"Medianamente Corrosivo",IF(R25>10000,"Despreciable","N/A"))))) -> Muy Corrosivo | V25: =IF(S25<=500,"Muy Corrosivo",IF(S25<=1000,"Corrosivo",IF(S25<=2000,"Moderadamente Corrosivo",IF(S25<=10000,"Medianamente Corrosivo",IF(S25>10000,"Despreciable","N/A"))))) -> #DIV/0! | W25: =IF(T25<=500,"Muy Corrosivo",IF(T25<=1000,"Corrosivo",IF(T25<=2000,"Moderadamente Corrosivo",IF(T25<=10000,"Medianamente Corrosivo",IF(T25>10000,"Despreciable","N/A"))))) -> #DIV/0!
U26: =IF(R26<=500,"Muy Corrosivo",IF(R26<=1000,"Corrosivo",IF(R26<=2000,"Moderadamente Corrosivo",IF(R26<=10000,"Medianamente Corrosivo",IF(R26>10000,"Despreciable","N/A"))))) -> Muy Corrosivo | V26: =IF(S26<=500,"Muy Corrosivo",IF(S26<=1000,"Corrosivo",IF(S26<=2000,"Moderadamente Corrosivo",IF(S26<=10000,"Medianamente Corrosivo",IF(S26>10000,"Despreciable","N/A"))))) -> Muy Corrosivo | W26: =IF(T26<=500,"Muy Corrosivo",IF(T26<=1000,"Corrosivo",IF(T26<=2000,"Moderadamente Corrosivo",IF(T26<=10000,"Medianamente Corrosivo",IF(T26>10000,"Despreciable","N/A"))))) -> Muy Corrosivo
U27: =IF(R27<=500,"Muy Corrosivo",IF(R27<=1000,"Corrosivo",IF(R27<=2000,"Moderadamente Corrosivo",IF(R27<=10000,"Medianamente Corrosivo",IF(R27>10000,"Despreciable","N/A"))))) -> Muy Corrosivo | V27: =IF(S27<=500,"Muy Corrosivo",IF(S27<=1000,"Corrosivo",IF(S27<=2000,"Moderadamente Corrosivo",IF(S27<=10000,"Medianamente Corrosivo",IF(S27>10000,"Despreciable","N/A"))))) -> Muy Corrosivo | W27: =IF(T27<=500,"Muy Corrosivo",IF(T27<=1000,"Corrosivo",IF(T27<=2000,"Moderadamente Corrosivo",IF(T27<=10000,"Medianamente Corrosivo",IF(T27>10000,"Despreciable","N/A"))))) -> Muy Corrosivo
U28: =IF(R28<=500,"Muy Corrosivo",IF(R28<=1000,"Corrosivo",IF(R28<=2000,"Moderadamente Corrosivo",IF(R28<=10000,"Medianamente Corrosivo",IF(R28>10000,"Despreciable","N/A"))))) -> Muy Corrosivo | V28: =IF(S28<=500,"Muy Corrosivo",IF(S28<=1000,"Corrosivo",IF(S28<=2000,"Moderadamente Corrosivo",IF(S28<=10000,"Medianamente Corrosivo",IF(S28>10000,"Despreciable","N/A"))))) -> Muy Corrosivo | W28: =IF(T28<=500,"Muy Corrosivo",IF(T28<=1000,"Corrosivo",IF(T28<=2000,"Moderadamente Corrosivo",IF(T28<=10000,"Medianamente Corrosivo",IF(T28>10000,"Despreciable","N/A"))))) -> Muy Corrosivo
U29: =IF(R29<=500,"Muy Corrosivo",IF(R29<=1000,"Corrosivo",IF(R29<=2000,"Moderadamente Corrosivo",IF(R29<=10000,"Medianamente Corrosivo",IF(R29>10000,"Despreciable","N/A"))))) -> Muy Corrosivo | V29: =IF(S29<=500,"Muy Corrosivo",IF(S29<=1000,"Corrosivo",IF(S29<=2000,"Moderadamente Corrosivo",IF(S29<=10000,"Medianamente Corrosivo",IF(S29>10000,"Despreciable","N/A"))))) -> Muy Corrosivo | W29: =IF(T29<=500,"Muy Corrosivo",IF(T29<=1000,"Corrosivo",IF(T29<=2000,"Moderadamente Corrosivo",IF(T29<=10000,"Medianamente Corrosivo",IF(T29>10000,"Despreciable","N/A"))))) -> Muy Corrosivo
U30: =IF(R30<=500,"Muy Corrosivo",IF(R30<=1000,"Corrosivo",IF(R30<=2000,"Moderadamente Corrosivo",IF(R30<=10000,"Medianamente Corrosivo",IF(R30>10000,"Despreciable","N/A"))))) -> Muy Corrosivo | V30: =IF(S30<=500,"Muy Corrosivo",IF(S30<=1000,"Corrosivo",IF(S30<=2000,"Moderadamente Corrosivo",IF(S30<=10000,"Medianamente Corrosivo",IF(S30>10000,"Despreciable","N/A"))))) -> Muy Corrosivo | W30: =IF(T30<=500,"Muy Corrosivo",IF(T30<=1000,"Corrosivo",IF(T30<=2000,"Moderadamente Corrosivo",IF(T30<=10000,"Medianamente Corrosivo",IF(T30>10000,"Despreciable","N/A"))))) -> Muy Corrosivo
U31: =IF(R31<=500,"Muy Corrosivo",IF(R31<=1000,"Corrosivo",IF(R31<=2000,"Moderadamente Corrosivo",IF(R31<=10000,"Medianamente Corrosivo",IF(R31>10000,"Despreciable","N/A"))))) -> Muy Corrosivo | V31: =IF(S31<=500,"Muy Corrosivo",IF(S31<=1000,"Corrosivo",IF(S31<=2000,"Moderadamente Corrosivo",IF(S31<=10000,"Medianamente Corrosivo",IF(S31>10000,"Despreciable","N/A"))))) -> Muy Corrosivo | W31: =IF(T31<=500,"Muy Corrosivo",IF(T31<=1000,"Corrosivo",IF(T31<=2000,"Moderadamente Corrosivo",IF(T31<=10000,"Medianamente Corrosivo",IF(T31>10000,"Despreciable","N/A"))))) -> Muy Corrosivo
U32: =IF(R32<=500,"Muy Corrosivo",IF(R32<=1000,"Corrosivo",IF(R32<=2000,"Moderadamente Corrosivo",IF(R32<=10000,"Medianamente Corrosivo",IF(R32>10000,"Despreciable","N/A"))))) -> Muy Corrosivo | V32: =IF(S32<=500,"Muy Corrosivo",IF(S32<=1000,"Corrosivo",IF(S32<=2000,"Moderadamente Corrosivo",IF(S32<=10000,"Medianamente Corrosivo",IF(S32>10000,"Despreciable","N/A"))))) -> Muy Corrosivo | W32: =IF(T32<=500,"Muy Corrosivo",IF(T32<=1000,"Corrosivo",IF(T32<=2000,"Moderadamente Corrosivo",IF(T32<=10000,"Medianamente Corrosivo",IF(T32>10000,"Despreciable","N/A"))))) -> Muy Corrosivo
U33: =IF(R33<=500,"Muy Corrosivo",IF(R33<=1000,"Corrosivo",IF(R33<=2000,"Moderadamente Corrosivo",IF(R33<=10000,"Medianamente Corrosivo",IF(R33>10000,"Despreciable","N/A"))))) -> Muy Corrosivo | V33: =IF(S33<=500,"Muy Corrosivo",IF(S33<=1000,"Corrosivo",IF(S33<=2000,"Moderadamente Corrosivo",IF(S33<=10000,"Medianamente Corrosivo",IF(S33>10000,"Despreciable","N/A"))))) -> Muy Corrosivo | W33: =IF(T33<=500,"Muy Corrosivo",IF(T33<=1000,"Corrosivo",IF(T33<=2000,"Moderadamente Corrosivo",IF(T33<=10000,"Medianamente Corrosivo",IF(T33>10000,"Despreciable","N/A"))))) -> Muy Corrosivo
U34: =IF(R34<=500,"Muy Corrosivo",IF(R34<=1000,"Corrosivo",IF(R34<=2000,"Moderadamente Corrosivo",IF(R34<=10000,"Medianamente Corrosivo",IF(R34>10000,"Despreciable","N/A"))))) -> Muy Corrosivo | V34: =IF(S34<=500,"Muy Corrosivo",IF(S34<=1000,"Corrosivo",IF(S34<=2000,"Moderadamente Corrosivo",IF(S34<=10000,"Medianamente Corrosivo",IF(S34>10000,"Despreciable","N/A"))))) -> Muy Corrosivo | W34: =IF(T34<=500,"Muy Corrosivo",IF(T34<=1000,"Corrosivo",IF(T34<=2000,"Moderadamente Corrosivo",IF(T34<=10000,"Medianamente Corrosivo",IF(T34>10000,"Despreciable","N/A"))))) -> Muy Corrosivo
U35: =IF(R35<=500,"Muy Corrosivo",IF(R35<=1000,"Corrosivo",IF(R35<=2000,"Moderadamente Corrosivo",IF(R35<=10000,"Medianamente Corrosivo",IF(R35>10000,"Despreciable","N/A"))))) -> Muy Corrosivo | V35: =IF(S35<=500,"Muy Corrosivo",IF(S35<=1000,"Corrosivo",IF(S35<=2000,"Moderadamente Corrosivo",IF(S35<=10000,"Medianamente Corrosivo",IF(S35>10000,"Despreciable","N/A"))))) -> Muy Corrosivo | W35: =IF(T35<=500,"Muy Corrosivo",IF(T35<=1000,"Corrosivo",IF(T35<=2000,"Moderadamente Corrosivo",IF(T35<=10000,"Medianamente Corrosivo",IF(T35>10000,"Despreciable","N/A"))))) -> Muy Corrosivo
U36: =IF(R36<=500,"Muy Corrosivo",IF(R36<=1000,"Corrosivo",IF(R36<=2000,"Moderadamente Corrosivo",IF(R36<=10000,"Medianamente Corrosivo",IF(R36>10000,"Despreciable","N/A"))))) -> Muy Corrosivo | V36: =IF(S36<=500,"Muy Corrosivo",IF(S36<=1000,"Corrosivo",IF(S36<=2000,"Moderadamente Corrosivo",IF(S36<=10000,"Medianamente Corrosivo",IF(S36>10000,"Despreciable","N/A"))))) -> Muy Corrosivo | W36: =IF(T36<=500,"Muy Corrosivo",IF(T36<=1000,"Corrosivo",IF(T36<=2000,"Moderadamente Corrosivo",IF(T36<=10000,"Medianamente Corrosivo",IF(T36>10000,"Despreciable","N/A"))))) -> Muy Corrosivo
U37: =IF(R37<=500,"Muy Corrosivo",IF(R37<=1000,"Corrosivo",IF(R37<=2000,"Moderadamente Corrosivo",IF(R37<=10000,"Medianamente Corrosivo",IF(R37>10000,"Despreciable","N/A"))))) -> Muy Corrosivo | V37: =IF(S37<=500,"Muy Corrosivo",IF(S37<=1000,"Corrosivo",IF(S37<=2000,"Moderadamente Corrosivo",IF(S37<=10000,"Medianamente Corrosivo",IF(S37>10000,"Despreciable","N/A"))))) -> Muy Corrosivo | W37: =IF(T37<=500,"Muy Corrosivo",IF(T37<=1000,"Corrosivo",IF(T37<=2000,"Moderadamente Corrosivo",IF(T37<=10000,"Medianamente Corrosivo",IF(T37>10000,"Despreciable","N/A"))))) -> Muy Corrosivo
... U244: =IF(R244<=500,"Muy Corrosivo",IF(R244<=1000,"Corrosivo",IF(R244<=2000,"Moderadamente Corrosivo",IF(R244<=10000,"Medianamente Corrosivo",IF(R244>10000,"Despreciable","N/A"))))) -> Muy Corrosivo | V244: =IF(S244<=500,"Muy Corrosivo",IF(S244<=1000,"Corrosivo",IF(S244<=2000,"Moderadamente Corrosivo",IF(S244<=10000,"Medianamente Corrosivo",IF(S244>10000,"Despreciable","N/A"))))) -> Muy Corrosivo | W244: =IF(T244<=500,"Muy Corrosivo",IF(T244<=1000,"Corrosivo",IF(T244<=2000,"Moderadamente Corrosivo",IF(T244<=10000,"Medianamente Corrosivo",IF(T244>10000,"Despreciable","N/A"))))) -> Muy Corrosivo
B245: Poste | P245: =2*PI()*J245*300 -> 0 | R245: =2*PI()*F245*100 -> 0
B246: Potrero | P246: =2*PI()*J246*300 -> 0 | R246: =2*PI()*F246*100 -> 0 | U246: =COUNTIF($U$9:$U$244,"Despreciable") -> 0 | V246: =(U246/236)*100 -> 0
B247: Potrero | P247: =2*PI()*J247*300 -> 0 | R247: =2*PI()*F247*100 -> 0 | U247: =COUNTIF($U$9:$U$244,"Medianamente Corrosivo") -> 0 | V247: =(U247/236)*100 -> 0
B248: Potrero | P248: =2*PI()*J248*300 -> 0 | R248: =2*PI()*F248*100 -> 0 | U248: =COUNTIF($U$9:$U$244,"Moderadamente Corrosivo") -> 0 | V248: =(U248/236)*100 -> 0
B249: Poste | P249: =2*PI()*J249*300 -> 0 | R249: =2*PI()*F249*100 -> 0 | U249: =COUNTIF($U$9:$U$244,"Muy corrosivo") -> 236 | V249: =(U249/236)*100 -> 100
B250: Potrero | P250: =2*PI()*J250*300 -> 0 | R250: =2*PI()*F250*100 -> 0 | U250: =COUNTIF($U$9:$U$244,"corrosivo") -> 0 | V250: =(U250/236)*100 -> 0
B251: Potrero | P251: =2*PI()*J251*300 -> 0 | R251: =2*PI()*F251*100 -> 0
...

Sheet Gráfica Resistividad
E3: GERENCIA DE INTEGRIDAD Y CONFIABILIDAD PERFIL DE RESISTIVIDAD ELÉCTRICA DEL TERRENO | J3: Código:
J5: Revisión:
J6: Emisión:
J7: Página _ de _
T10: 0 | U10: 500 | V10: 1000 | W10: 2000 | X10: 10000
T11: 4000 | U11: 500 | V11: 1000 | W11: 2000 | X11: 10000
C31: FECHA: | D31: =Informe!G6 -> 0 | F31: OBSERVACIONES
C32: GASODUCTO: | D32: =Informe!G7 -> Mariquita_Cali | F32: Se realizaron mediciones de resistividades cada 250 m de distacia a 1,2 y 3 metros de profundidad con el objetivo de estimar el grado de corrosividad del suelo en las ubicaciones de los defectos encontrados en la tubería. Para la ubicación medida, se encontró que la tubería se encuentra en zonas desde corrosividad despreciable hasta medianamente corrosivas (Ver pestaña Datos). Basado en la totalidad de las mediciones para 1, 2 y 3 m de profundidad se puede considerar que el 94.2% aproximadamente de los registros corresponden a una zona de corrosividad despreciable y 5.8% a zonas medianamente corrosivas.
C33: TRAMO | D33: =Informe!G8 -> 0
C34: LONGITUD: | D34: =Informe!G36+Informe!G35 -> 4
C35: DIÁMETRO: | D35: =Informe!U9 -> 0
C36: RECUBRIMIENTO: | D36: =Informe!U8 -> 0

Sheet Hallazgos
D1: GERENCIA DE INTEGRIDAD Y CONFIABILIDAD FORMATO HALLAZGOS | M1: Código:
M2: Revisión:
M3: Emisión:
M4: Página _ de _
A6: Fecha | C6: =Informe!G6 -> 0 | J6: Tipo de inspección | L6: =Informe!P33 -> Inspección indirecta del estado del Recubrimiento
A7: Gasoducto | C7: =Informe!G7 -> Mariquita_Cali | J7: No de contrato | L7: =Informe!AE6 -> 551007370
A8: Tramo | C8: =Informe!G8 -> 0 | J8: Contratista | L8: =Informe!AE7 -> PCC
A9: Inspector | C9: =Informe!G9 -> 0 | J9: OT | L9: =Informe!AE8 -> 0
A11: ÍTEM | B11: ABSCISA INICIO | C11: ABSCISA FIN | D11: LONGITUD [m] | E11: GASODUCTO | F11: TRAMO | G11: LATITUD INICIO | H11: LONGITUD INICIO | I11: LATITUD FIN | J11: LONGITUD FIN | K11: FECHA | L11: TIPO DE HALLAZGO | M11: DESCRIPCIÓN DEL HALLAZGO
C122: ELABORÓ | G122: REVISÓ | L122: APROBÓ
A123: Nombre | L123: =Informe!W99 -> Alejando Rivera
A124: Cargo | C124: =Informe!D100 -> Ingeniero Junior | G124: =Informe!O100 -> Ingeniero Residente | L124: =Informe!W100 -> Coordinador de Proyectos
A125: Empresa | C125: =Informe!D101 -> Protección Catódica de Colombia SAS | G125: =Informe!O101 -> Protección Catódica de Colombia SAS | L125: =Informe!W101 -> Protección Catódica de Colombia SAS
